Workbook

Sheet Test Cases
A1: Test Case ID | B1: Use Case | C1: Test Case Title | D1: Precondition | E1: Test Steps | F1: Test Data | G1: Expected Result | H1: Actual Result | I1: Status | J1: Defect ID | K1: Tester
A2: TC-01-01 | B2: UC01 – Đăng nhập (Login) | C2: Đăng nhập username/password hợp lệ | D2: Đã có tài khoản; đang ở trang Đăng nhập | E2: 1. Nhập username hợp lệ 2. Nhập password đúng 3. Nhấn Đăng nhập | F2: user: kaiko_test / pass: Test@123 | G2: Đăng nhập thành công, chuyển tới Dashboard | H2: Vào Dashboard đúng như mong đợi | I2: Pass | K2: Thịnh
A3: TC-01-02 | B3: UC01 – Đăng nhập (Login) | C3: Đăng nhập sai mật khẩu | D3: Đã có tài khoản | E3: 1. Nhập username đúng 2. Nhập password sai 3. Nhấn Đăng nhập | F3: pass: SaiMatKhau | G3: Hiển thị thông báo lỗi, không đăng nhập | H3: Báo lỗi thông tin không đúng | I3: Pass | K3: Thịnh
A4: TC-01-03 | B4: UC01 – Đăng nhập (Login) | C4: Bỏ trống username | D4: Ở trang Đăng nhập | E4: 1. Để trống username 2. Nhập password 3. Nhấn Đăng nhập | F4: username rỗng | G4: Chặn submit / báo trường bắt buộc | H4: Không cho đăng nhập | I4: Pass | K4: Thịnh
A5: TC-01-04 | B5: UC01 – Đăng nhập (Login) | C5: Đăng nhập bằng Clerk OAuth (Google) | D5: Có tài khoản Google | E5: 1. Nhấn 'Đăng nhập với Google' 2. Chọn tài khoản Google | F5: Google account | G5: Đăng nhập OAuth thành công, vào Dashboard | H5: Đăng nhập Google thành công | I5: Pass | K5: Linh
A6: TC-01-05 | B6: UC01 – Đăng nhập (Login) | C6: Đăng nhập username không tồn tại | D6: Ở trang Đăng nhập | E6: 1. Nhập username chưa đăng ký 2. Nhập password bất kỳ 3. Đăng nhập | F6: user: notexist | G6: Báo lỗi tài khoản không tồn tại | H6: Báo lỗi đúng | I6: Pass | K6: Linh
A7: TC-02-01 | B7: UC02 – Đăng ký tài khoản (Register) | C7: Đăng ký tài khoản mới hợp lệ | D7: Ở trang Đăng ký | E7: 1. Nhập username mới 2. Nhập password hợp lệ 3. Nhấn Đăng ký | F7: user: kaiko_new / pass: New@123 | G7: Tạo tài khoản thành công | H7: Tạo tài khoản thành công | I7: Pass | K7: Thịnh
A8: TC-02-02 | B8: UC02 – Đăng ký tài khoản (Register) | C8: Đăng ký username đã tồn tại | D8: Username đã tồn tại trong hệ thống | E8: 1. Nhập username đã có 2. Nhập password 3. Đăng ký | F8: user: kaiko_test | G8: Báo lỗi username đã tồn tại | H8: Báo trùng username | I8: Pass | K8: Thịnh
A9: TC-02-03 | B9: UC02 – Đăng ký tài khoản (Register) | C9: Đăng ký với mật khẩu quá ngắn | D9: Ở trang Đăng ký | E9: 1. Nhập username mới 2. Nhập password 2 ký tự 3. Đăng ký | F9: pass: 12 | G9: Cảnh báo mật khẩu không hợp lệ | H9: Chặn mật khẩu yếu | I9: Pass | K9: Linh
A10: TC-02-04 | B10: UC02 – Đăng ký tài khoản (Register) | C10: Bỏ trống trường bắt buộc | D10: Ở trang Đăng ký | E10: 1. Để trống password 2. Nhấn Đăng ký | F10: password rỗng | G10: Báo trường bắt buộc, không tạo | H10: Không tạo tài khoản | I10: Pass | K10: Linh
A11: TC-02-05 | B11: UC02 – Đăng ký tài khoản (Register) | C11: Đăng ký xong đăng nhập được | D11: Vừa đăng ký thành công | E11: 1. Đăng xuất 2. Đăng nhập lại bằng tài khoản vừa tạo | F11: kaiko_new / New@123 | G11: Đăng nhập thành công | H11: Đăng nhập được ngay | I11: Pass | K11: Bảo
A12: TC-03-01 | B12: UC03 – Tìm trận nhanh (Find-Match) | C12: Tìm trận Video ghép cặp cùng tier | D12: Đã đăng nhập; 2 người chơi cùng tier | E12: 1. Chọn chế độ Video 2. Nhấn Tìm trận (cả 2 phiên) | F12: 2 account cùng level | G12: Ghép cặp, vào phòng chờ ReadyCheck | H12: Ghép cặp thành công | I12: Pass | K12: Bảo
A13: TC-03-02 | B13: UC03 – Tìm trận nhanh (Find-Match) | C13: Tìm trận Text mode | D13: Đã đăng nhập; 2 người chơi | E13: 1. Chọn chế độ Text 2. Nhấn Tìm trận (cả 2) | F13: text_1v1 | G13: Ghép cặp chế độ text, phân phe ngẫu nhiên | H13: Ghép cặp text thành công | I13: Pass | K13: Bảo
... A15: TC-03-04 | B15: UC03 – Tìm trận nhanh (Find-Match) | C15: Không có đối thủ trong hàng chờ | D15: Chỉ 1 người tìm trận | E15: 1. Nhấn Tìm trận 2. Chờ | F15: 1 account | G15: Hiển thị trạng thái đang chờ, không lỗi | H15: Hiển thị đang tìm đối thủ | I15: Pass | K15: Thanh
A16: TC-03-05 | B16: UC03 – Tìm trận nhanh (Find-Match) | C16: Mất kết nối WebSocket khi đang chờ ghép | D16: Đang chờ ghép; mạng yếu | E16: 1. Nhấn Tìm trận 2. Ngắt mạng tạm thời | F16: mạng chập chờn | G16: Hệ thống báo mất kết nối & cho thử lại | H16: Treo ở màn hình chờ, không xử lý timeout | I16: Fail | J16: DEF-03 | K16: Thanh
A17: TC-04-01 | B17: UC04 – Tranh biện Video 1v1 (Video Debate) | C17: Hiển thị video 2 bên khi vào phòng | D17: Đã ghép cặp; cấp quyền camera/mic | E17: 1. Vào phòng 2. Quan sát ô video 2 người | F17: 2 máy có webcam | G17: Thấy video của cả 2 người chơi | H17: Đôi khi video đối thủ chưa hiện do stream attach trễ | I17: Fail | J17: DEF-01 | K17: Thịnh
A18: TC-04-02 | B18: UC04 – Tranh biện Video 1v1 (Video Debate) | C18: Speech-to-text tiếng Việt | D18: Trong phòng debate, mic bật | E18: 1. Nói 1 câu tiếng Việt 2. Xem transcript | F18: Giọng nói tiếng Việt | G18: Sinh transcript tiếng Việt đúng | H18: Không nhận tiếng Việt khi locale browser khác vi-VN | I18: Fail | J18: DEF-02 | K18: Thịnh
A19: TC-04-03 | B19: UC04 – Tranh biện Video 1v1 (Video Debate) | C19: Từ chối quyền camera/mic | D19: Vào phòng video | E19: 1. Vào phòng 2. Chọn 'Chặn' quyền camera/mic | F19: deny permission | G19: Báo lỗi, chế độ video không chạy | H19: Thông báo cần cấp quyền | I19: Pass | K19: Linh
A20: TC-04-04 | B20: UC04 – Tranh biện Video 1v1 (Video Debate) | C20: Bật/tắt mic và camera | D20: Đang trong phòng | E20: 1. Nhấn nút tắt mic 2. Nhấn tắt camera | F20: — | G20: Mic/camera bật tắt đúng trạng thái | H20: Controls hoạt động đúng | I20: Pass | K20: Linh
A21: TC-04-05 | B21: UC04 – Tranh biện Video 1v1 (Video Debate) | C21: Chạy Video Debate trên Firefox | D21: Mở app bằng Firefox | E21: 1. Vào phòng video trên Firefox 2. Thử nói | F21: Firefox browser | G21: Cảnh báo trình duyệt không hỗ trợ | H21: Speech API không chạy trên Firefox | I21: Fail | J21: DEF-04 | K21: Bảo
A22: TC-05-01 | B22: UC05 – Nhận cảnh báo ngụy biện (Fallacy Alert) | C22: Phát hiện ngụy biện ad hominem | D22: Đang trong trận, có transcript | E22: 1. Nói câu công kích cá nhân 2. Chờ phân tích | F22: 'Anh dốt nên lập luận sai' | G22: Hiện pop-up FallacyAlert 'Công kích cá nhân' | H22: Hiện cảnh báo đúng loại | I22: Pass | K22: Thịnh
A23: TC-05-02 | B23: UC05 – Nhận cảnh báo ngụy biện (Fallacy Alert) | C23: Câu quá ngắn (<10 ký tự) bị bỏ qua | D23: Đang trong trận | E23: 1. Nói/gõ 1 câu rất ngắn | F23: 'Ừ' | G23: Không phân tích, không cảnh báo | H23: Bỏ qua đúng | I23: Pass | K23: Thịnh
A24: TC-05-03 | B24: UC05 – Nhận cảnh báo ngụy biện (Fallacy Alert) | C24: Câu không ngụy biện | D24: Đang trong trận | E24: 1. Nói câu lập luận hợp lệ | F24: câu hợp lý | G24: Không hiển thị cảnh báo ngụy biện | H24: Không cảnh báo | I24: Pass | K24: Linh
A25: TC-05-04 | B25: UC05 – Nhận cảnh báo ngụy biện (Fallacy Alert) | C25: Fallback Gemini khi AI service offline | D25: AI_SERVICE_URL không cấu hình | E25: 1. Nói câu ngụy biện 2. Chờ kết quả | F25: service offline | G25: Backend fallback Gemini vẫn trả kết quả | H25: Fallback Gemini hoạt động | I25: Pass | K25: Bảo
A26: TC-05-05 | B26: UC05 – Nhận cảnh báo ngụy biện (Fallacy Alert) | C26: Hiển thị nhãn tiếng Việt | D26: Có cảnh báo ngụy biện | E26: 1. Gây một ngụy biện 2. Xem nhãn hiển thị | F26: — | G26: Nhãn hiển thị tiếng Việt (LABEL_VI) | H26: Nhãn tiếng Việt đúng | I26: Pass | K26: Bảo
A27: TC-06-01 | B27: UC06 – Xem Scoreboard & phân tích sau trận | C27: Hiển thị Scoreboard cuối trận | D27: Trận vừa kết thúc | E27: 1. Kết thúc trận 2. Xem Scoreboard | F27: — | G27: Hiện điểm tổng của 2 người chơi | H27: Scoreboard hiển thị điểm | I27: Pass | K27: Thịnh
A28: TC-06-02 | B28: UC06 – Xem Scoreboard & phân tích sau trận | C28: Nhận xét chi tiết từng tiêu chí | D28: Ở màn Scoreboard | E28: 1. Xem phần nhận xét AI | F28: — | G28: Có nhận xét cho logic/dẫn chứng/diễn đạt | H28: Có nhận xét chi tiết | I28: Pass | K28: Thịnh
A29: TC-06-03 | B29: UC06 – Xem Scoreboard & phân tích sau trận | C29: Tuyên bố người thắng đúng điểm | D29: Ở màn Scoreboard | E29: 1. So điểm 2 bên 2. Xem người thắng | F29: — | G29: Người điểm cao hơn được tuyên thắng | H29: Người thắng đúng | I29: Pass | K29: Linh
A30: TC-06-04 | B30: UC06 – Xem Scoreboard & phân tích sau trận | C30: Lưu kết quả vào lịch sử | D30: Trận kết thúc, đã đăng nhập | E30: 1. Kết thúc trận 2. Mở lịch sử ở Dashboard | F30: — | G30: Trận mới xuất hiện trong lịch sử (PostgreSQL) | H30: Lưu lịch sử thành công | I30: Pass | K30: Bảo
A31: TC-06-05 | B31: UC06 – Xem Scoreboard & phân tích sau trận | C31: Chấm điểm khi Gemini bị rate limit | D31: Nhiều trận đồng thời, quota thấp | E31: 1. Kết thúc nhiều trận cùng lúc | F31: free-tier quota | G31: Vẫn chấm điểm hoặc báo lỗi rõ ràng | H31: Chấm điểm lỗi/không hiện khi bị rate limit | I31: Fail | J31: DEF-05 | K31: Bảo
A32: TC-07-01 | B32: UC07 – Luyện tập với AI (Solo Mode) | C32: Bắt đầu Solo vs AI (text) | D32: Đã đăng nhập | E32: 1. Chọn Solo Mode 2. Bắt đầu trận với AI | F32: — | G32: Vào phòng tranh biện với Gemini | H32: Vào trận Solo thành công | I32: Pass | K32: Thanh
A33: TC-07-02 | B33: UC07 – Luyện tập với AI (Solo Mode) | C33: AI phản hồi và phân tích inline | D33: Đang trong trận Solo | E33: 1. Gõ 1 lập luận 2. Gửi | F33: 'Tôi cho rằng...' | G33: AI phản hồi + phân tích ngụy biện lượt đó | H33: AI phản hồi + phân tích | I33: Pass | K33: Thanh
A34: TC-07-03 | B34: UC07 – Luyện tập với AI (Solo Mode) | C34: Tự kết thúc khi hết thời gian | D34: Đang trong trận Solo/Text | E34: 1. Chờ hết 30 phút | F34: timer 30' | G34: Trận tự kết thúc và chấm điểm | H34: Tự kết thúc & chấm điểm | I34: Pass | K34: Linh
A35: TC-07-04 | B35: UC07 – Luyện tập với AI (Solo Mode) | C35: Sinh chủ đề ngẫu nhiên | D35: Bắt đầu trận mới | E35: 1. Bắt đầu Solo Mode | F35: — | G35: Hệ thống sinh random topic hợp lệ | H35: Có chủ đề ngẫu nhiên | I35: Pass | K35: Linh
A36: TC-07-05 | B36: UC07 – Luyện tập với AI (Solo Mode) | C36: Phát hiện nội dung copy từ AI | D36: Đang trong trận text | E36: 1. Dán 1 đoạn văn kiểu ChatGPT 2. Gửi | F36: đoạn văn AI | G36: Cảnh báo is_ai_generated | H36: Cảnh báo nội dung AI | I36: Pass | K36: Bảo
A37: TC-08-01 | B37: UC08 – Xem lịch sử trận & ELO | C37: Xem lịch sử trận trong Dashboard | D37: Đã đăng nhập, có ≥1 trận | E37: 1. Mở Dashboard 2. Vào tab Lịch sử | F37: — | G37: Danh sách các trận đã chơi hiển thị | H37: Lịch sử hiển thị đúng | I37: Pass | K37: Thịnh
A38: TC-08-02 | B38: UC08 – Xem lịch sử trận & ELO | C38: Bảng xếp hạng leaderboard | D38: Đã đăng nhập | E38: 1. Mở tab Bảng xếp hạng | F38: — | G38: Leaderboard hiển thị theo điểm/ELO | H38: Leaderboard đúng thứ hạng | I38: Pass | K38: Thịnh
A39: TC-08-03 | B39: UC08 – Xem lịch sử trận & ELO | C39: ELO cập nhật sau trận | D39: Vừa kết thúc 1 trận | E39: 1. Ghi điểm ELO trước 2. Chơi 1 trận 3. Xem lại ELO | F39: — | G39: ELO/điểm được cập nhật | H39: ELO cập nhật sau trận | I39: Pass | K39: Linh
A40: TC-08-04 | B40: UC08 – Xem lịch sử trận & ELO | C40: Người chơi mới chưa có trận | D40: Tài khoản mới đăng ký | E40: 1. Đăng nhập tài khoản mới 2. Mở Lịch sử | F40: account mới | G40: Lịch sử trống, không lỗi | H40: Hiển thị trống, không lỗi | I40: Pass | K40: Bảo
A41: TC-08-05 | B41: UC08 – Xem lịch sử trận & ELO | C41: Xem chi tiết một trận | D41: Có trận trong lịch sử | E41: 1. Nhấn vào 1 trận 2. Xem chi tiết | F41: — | G41: Hiện transcript, điểm, ngụy biện của trận | H41: Xem chi tiết trận đúng | I41: Pass | K41: Bảo
...

Sheet Test Summary
A1: Test Summary Report – KaiKo (PA4)
A3: Use Case | B3: Use Case Name | C3: # Test Cases | D3: # Passed | E3: # Failed | F3: Pass Rate
A4: UC01 | B4: Đăng nhập (Login) | C4: =COUNTIF('Test Cases'!$A:$A,"TC-01-*") | D4: =COUNTIFS('Test Cases'!$A:$A,"TC-01-*",'Test Cases'!$I:$I,"Pass") | E4: =COUNTIFS('Test Cases'!$A:$A,"TC-01-*",'Test Cases'!$I:$I,"Fail") | F4: =IF(C4=0,0,D4/C4)
A5: UC02 | B5: Đăng ký tài khoản (Register) | C5: =COUNTIF('Test Cases'!$A:$A,"TC-02-*") | D5: =COUNTIFS('Test Cases'!$A:$A,"TC-02-*",'Test Cases'!$I:$I,"Pass") | E5: =COUNTIFS('Test Cases'!$A:$A,"TC-02-*",'Test Cases'!$I:$I,"Fail") | F5: =IF(C5=0,0,D5/C5)
A6: UC03 | B6: Tìm trận nhanh (Find-Match) | C6: =COUNTIF('Test Cases'!$A:$A,"TC-03-*") | D6: =COUNTIFS('Test Cases'!$A:$A,"TC-03-*",'Test Cases'!$I:$I,"Pass") | E6: =COUNTIFS('Test Cases'!$A:$A,"TC-03-*",'Test Cases'!$I:$I,"Fail") | F6: =IF(C6=0,0,D6/C6)
A7: UC04 | B7: Tranh biện Video 1v1 | C7: =COUNTIF('Test Cases'!$A:$A,"TC-04-*") | D7: =COUNTIFS('Test Cases'!$A:$A,"TC-04-*",'Test Cases'!$I:$I,"Pass") | E7: =COUNTIFS('Test Cases'!$A:$A,"TC-04-*",'Test Cases'!$I:$I,"Fail") | F7: =IF(C7=0,0,D7/C7)
A8: UC05 | B8: Nhận cảnh báo ngụy biện | C8: =COUNTIF('Test Cases'!$A:$A,"TC-05-*") | D8: =COUNTIFS('Test Cases'!$A:$A,"TC-05-*",'Test Cases'!$I:$I,"Pass") | E8: =COUNTIFS('Test Cases'!$A:$A,"TC-05-*",'Test Cases'!$I:$I,"Fail") | F8: =IF(C8=0,0,D8/C8)
A9: UC06 | B9: Scoreboard & phân tích | C9: =COUNTIF('Test Cases'!$A:$A,"TC-06-*") | D9: =COUNTIFS('Test Cases'!$A:$A,"TC-06-*",'Test Cases'!$I:$I,"Pass") | E9: =COUNTIFS('Test Cases'!$A:$A,"TC-06-*",'Test Cases'!$I:$I,"Fail") | F9: =IF(C9=0,0,D9/C9)
A10: UC07 | B10: Luyện tập với AI (Solo) | C10: =COUNTIF('Test Cases'!$A:$A,"TC-07-*") | D10: =COUNTIFS('Test Cases'!$A:$A,"TC-07-*",'Test Cases'!$I:$I,"Pass") | E10: =COUNTIFS('Test Cases'!$A:$A,"TC-07-*",'Test Cases'!$I:$I,"Fail") | F10: =IF(C10=0,0,D10/C10)
A11: UC08 | B11: Lịch sử trận & ELO | C11: =COUNTIF('Test Cases'!$A:$A,"TC-08-*") | D11: =COUNTIFS('Test Cases'!$A:$A,"TC-08-*",'Test Cases'!$I:$I,"Pass") | E11: =COUNTIFS('Test Cases'!$A:$A,"TC-08-*",'Test Cases'!$I:$I,"Fail") | F11: =IF(C11=0,0,D11/C11)
A12: UC09 | B12: Xem trực tiếp trận đấu (Spectate) | C12: =COUNTIF('Test Cases'!$A:$A,"TC-09-*") | D12: =COUNTIFS('Test Cases'!$A:$A,"TC-09-*",'Test Cases'!$I:$I,"Pass") | E12: =COUNTIFS('Test Cases'!$A:$A,"TC-09-*",'Test Cases'!$I:$I,"Fail") | F12: =IF(C12=0,0,D12/C12)
A13: UC10 | B13: Thành tựu & Cửa hàng (Achievement & Store) | C13: =COUNTIF('Test Cases'!$A:$A,"TC-10-*") | D13: =COUNTIFS('Test Cases'!$A:$A,"TC-10-*",'Test Cases'!$I:$I,"Pass") | E13: =COUNTIFS('Test Cases'!$A:$A,"TC-10-*",'Test Cases'!$I:$I,"Fail") | F13: =IF(C13=0,0,D13/C13)
A14: TỔNG | B14: Tất cả use-case | C14: =SUM(C4:C13) | D14: =SUM(D4:D13) | E14: =SUM(E4:E13) | F14: =IF(C14=0,0,D14/C14)
A16: Số use-case được test: | C16: =COUNTA(A4:A13)
A17: Ghi chú: | B17: Mỗi test case Fail đều có Defect liên kết ở sheet 'Defects'.

Sheet Defects
A1: Defect ID | B1: Linked Test Case | C1: Use Case | D1: Description | E1: Severity | F1: Priority | G1: Status | H1: Suggested Fix
A2: DEF-01 | B2: TC-04-01 | C2: UC04 | D2: Video P2P của đối thủ đôi khi chưa attach vào thẻ <video> kịp khi vừa vào phòng | E2: Major | F2: High | G2: Open | H2: Đợi 'ontrack' rồi mới gán srcObject; thêm retry attach stream
A3: DEF-02 | B3: TC-04-02 | C3: UC04 | D3: Speech-to-text không nhận tiếng Việt khi locale trình duyệt khác vi-VN | E3: Major | F3: High | G3: Open | H3: Set recognition.lang='vi-VN' cố định thay vì theo locale browser
A4: DEF-03 | B4: TC-03-05 | C4: UC03 | D4: Không xử lý timeout khi mất kết nối WebSocket lúc chờ ghép cặp | E4: Medium | F4: Medium | G4: Open | H4: Thêm heartbeat/timeout + tự động thử ghép lại và thông báo cho người dùng
A5: DEF-04 | B5: TC-04-05 | C5: UC04 | D5: Firefox không hỗ trợ Web Speech API → chế độ giọng nói không chạy | E5: Medium | F5: Low | G5: Open | H5: Phát hiện trình duyệt, cảnh báo & gợi ý dùng Chrome/Edge (giới hạn đã biết)
A6: DEF-05 | B6: TC-06-05 | C6: UC06 | D6: Gemini free-tier bị rate limit khi nhiều trận chấm điểm đồng thời | E6: Medium | F6: Medium | G6: Open | H6: Thêm hàng đợi/retry với backoff; cache; nâng quota API
A7: DEF-06 | B7: TC-09-05 | C7: UC09 | D7: Khi không có phòng public nào đang debate, trang Live không hiển thị trạng thái rỗng rõ ràng (đôi lúc hiện màn hình trắng/loading vô hạn) | E7: Minor | F7: Low | G7: Open | H7: Thêm empty-state UI: thông báo 'Hiện không có trận nào đang diễn ra' khi danh sách rỗng
A8: DEF-07 | B8: TC-10-05 | C8: UC10 | D8: Store cho phép mua trùng vật phẩm đã sở hữu và trừ Store Points lần thứ hai (thiếu kiểm tra user_items trước khi tạo giao dịch) | E8: Major | F8: High | G8: Open | H8: Kiểm tra user_items trước khi xử lý giao dịch mua; trả về HTTP 409 nếu đã sở hữu
